Workbook

Sheet Dados
A1: cod_ibge7 | B1: cod_ibge6 | C1: municipio | D1: uf | E1: co_regiao_saude | F1: no_regiao_saude | G1: populacao_2025 | H1: municipio_pequeno | I1: fp_total | J1: fp_so_hipertensao | K1: fp_so_diabetes | L1: fp_hipertensao_e_diabetes | M1: fp_asma | N1: alto_custo_pacientes | O1: quimioterapia_pacientes | P1: radioterapia_pacientes | Q1: hiv_pessoas_em_tratamento_2022 | R1: fp_total_por_mil_hab | S1: fp_so_hipertensao_por_mil_hab | T1: fp_so_diabetes_por_mil_hab | U1: fp_hipertensao_e_diabetes_por_mil_hab | V1: fp_asma_por_mil_hab | W1: alto_custo_pacientes_por_mil_hab | X1: quimioterapia_pacientes_por_mil_hab | Y1: fp_total_regiao_saude | Z1: fp_so_hipertensao_regiao_saude | AA1: fp_so_diabetes_regiao_saude | AB1: fp_hipertensao_e_diabetes_regiao_saude | AC1: fp_asma_regiao_saude | AD1: alto_custo_pacientes_regiao_saude | AE1: quimioterapia_pacientes_regiao_saude | AF1: radioterapia_pacientes_regiao_saude | AG1: fp_total_por_mil_hab_regiao_saude | AH1: bolso_anual_minimo_rs | AI1: bolso_anual_mediano_rs | AJ1: txt_farmacia_popular | AK1: txt_bolso
A2: 1100015 | B2: 110001 | C2: Alta Floresta D'Oeste | D2: RO | E2: 11005 | F2: Zona da Mata | G2: 22787 | H2: =G2<'Programas e Observações'!$C$11 -> FALSE | I2: 344 | J2: 204 | K2: 21 | L2: 74 | M2: 2 | N2: 361 | O2: 59 | P2: 1 | R2: =IF(G2>0,1000*I2/G2,0) -> 15.096327 | S2: =IF(G2>0,1000*J2/G2,0) -> 8.9524729 | T2: =IF(G2>0,1000*K2/G2,0) -> 0.92157809 | U2: =IF(G2>0,1000*L2/G2,0) -> 3.2474657 | V2: =IF(G2>0,1000*M2/G2,0) -> 0.087769342 | W2: =IF(G2>0,1000*N2/G2,0) -> 15.842366 | X2: =IF(G2>0,1000*O2/G2,0) -> 2.5891956 | Y2: =SUMIFS($I$2:$I$5572,$E$2:$E$5572,E2) -> 3387 | Z2: =SUMIFS($J$2:$J$5572,$E$2:$E$5572,E2) -> 1912 | AA2: =SUMIFS($K$2:$K$5572,$E$2:$E$5572,E2) -> 196 | AB2: =SUMIFS($L$2:$L$5572,$E$2:$E$5572,E2) -> 835 | AC2: =SUMIFS($M$2:$M$5572,$E$2:$E$5572,E2) -> 38 | AD2: =SUMIFS($N$2:$N$5572,$E$2:$E$5572,E2) -> 1751 | AE2: =SUMIFS($O$2:$O$5572,$E$2:$E$5572,E2) -> 314 | AF2: =SUMIFS($P$2:$P$5572,$E$2:$E$5572,E2) -> 7 | AG2: =IF(SUMIFS($G$2:$G$5572,$E$2:$E$5572,E2)>0,1000*Y2/SUMIFS($G$2:$G$5572,$E$2:$E$5572,E2),0) -> 24.545613 | AH2: =12*(J2*'Programas e Observações'!$C$8+K2*'Programas e Observações'!$C$9+L2*('Programas e Observações'!$C$8+'Programas e Observações'!$C$9)+M2*'Programas e Observações'!$C$10) -> 104658.36 | AI2: =12*(J2*'Programas e Observações'!$D$8+K2*'Programas e Observações'!$D$9+L2*('Programas e Observações'!$D$8+'Programas e Observações'!$D$9)+M2*'Programas e Observações'!$D$10) -> 206718.84 | AJ2: 299 moradores pegam remédio de pressão ou diabetes de graça na Farmácia Popular | AK2: Sem o programa, gastariam pelo menos R$ 105 mil por ano
A3: 1100023 | B3: 110002 | C3: Ariquemes | D3: RO | E3: 11001 | F3: Vale do Jamari | G3: 109170 | H3: =G3<'Programas e Observações'!$C$11 -> FALSE | I3: 1537 | J3: 633 | K3: 114 | L3: 234 | M3: 44 | N3: 963 | O3: 182 | P3: 6 | Q3: 335 | R3: =IF(G3>0,1000*I3/G3,0) -> 14.078959 | S3: =IF(G3>0,1000*J3/G3,0) -> 5.7982962 | T3: =IF(G3>0,1000*K3/G3,0) -> 1.0442429 | U3: =IF(G3>0,1000*L3/G3,0) -> 2.143446 | V3: =IF(G3>0,1000*M3/G3,0) -> 0.40304113 | W3: =IF(G3>0,1000*N3/G3,0) -> 8.8211047 | X3: =IF(G3>0,1000*O3/G3,0) -> 1.6671247 | Y3: =SUMIFS($I$2:$I$5572,$E$2:$E$5572,E3) -> 3070 | Z3: =SUMIFS($J$2:$J$5572,$E$2:$E$5572,E3) -> 1523 | AA3: =SUMIFS($K$2:$K$5572,$E$2:$E$5572,E3) -> 232 | AB3: =SUMIFS($L$2:$L$5572,$E$2:$E$5572,E3) -> 477 | AC3: =SUMIFS($M$2:$M$5572,$E$2:$E$5572,E3) -> 83 | AD3: =SUMIFS($N$2:$N$5572,$E$2:$E$5572,E3) -> 2055 | AE3: =SUMIFS($O$2:$O$5572,$E$2:$E$5572,E3) -> 401 | AF3: =SUMIFS($P$2:$P$5572,$E$2:$E$5572,E3) -> 13 | AG3: =IF(SUMIFS($G$2:$G$5572,$E$2:$E$5572,E3)>0,1000*Y3/SUMIFS($G$2:$G$5572,$E$2:$E$5572,E3),0) -> 12.973622 | AH3: =12*(J3*'Programas e Observações'!$C$8+K3*'Programas e Observações'!$C$9+L3*('Programas e Observações'!$C$8+'Programas e Observações'!$C$9)+M3*'Programas e Observações'!$C$10) -> 372657.72 | AI3: =12*(J3*'Programas e Observações'!$D$8+K3*'Programas e Observações'!$D$9+L3*('Programas e Observações'!$D$8+'Programas e Observações'!$D$9)+M3*'Programas e Observações'!$D$10) -> 692610.72 | AJ3: 981 moradores pegam remédio de pressão ou diabetes de graça na Farmácia Popular | AK3: Sem o programa, gastariam pelo menos R$ 373 mil por ano
A4: 1100031 | B4: 110003 | C4: Cabixi | D4: RO | E4: 11006 | F4: Cone Sul | G4: 5664 | H4: =G4<'Programas e Observações'!$C$11 -> TRUE | I4: 465 | J4: 220 | K4: 22 | L4: 179 | M4: 147 | N4: 25 | O4: 9 | P4: 0 | R4: =IF(G4>0,1000*I4/G4,0) -> 82.097458 | S4: =IF(G4>0,1000*J4/G4,0) -> 38.841808 | T4: =IF(G4>0,1000*K4/G4,0) -> 3.8841808 | U4: =IF(G4>0,1000*L4/G4,0) -> 31.603107 | V4: =IF(G4>0,1000*M4/G4,0) -> 25.95339 | W4: =IF(G4>0,1000*N4/G4,0) -> 4.4138418 | X4: =IF(G4>0,1000*O4/G4,0) -> 1.5889831 | Y4: =SUMIFS($I$2:$I$5572,$E$2:$E$5572,E4) -> 6176 | Z4: =SUMIFS($J$2:$J$5572,$E$2:$E$5572,E4) -> 3173 | AA4: =SUMIFS($K$2:$K$5572,$E$2:$E$5572,E4) -> 544 | AB4: =SUMIFS($L$2:$L$5572,$E$2:$E$5572,E4) -> 1434 | AC4: =SUMIFS($M$2:$M$5572,$E$2:$E$5572,E4) -> 238 | AD4: =SUMIFS($N$2:$N$5572,$E$2:$E$5572,E4) -> 1653 | AE4: =SUMIFS($O$2:$O$5572,$E$2:$E$5572,E4) -> 277 | AF4: =SUMIFS($P$2:$P$5572,$E$2:$E$5572,E4) -> 5 | AG4: =IF(SUMIFS($G$2:$G$5572,$E$2:$E$5572,E4)>0,1000*Y4/SUMIFS($G$2:$G$5572,$E$2:$E$5572,E4),0) -> 36.48889 | AH4: =12*(J4*'Programas e Observações'!$C$8+K4*'Programas e Observações'!$C$9+L4*('Programas e Observações'!$C$8+'Programas e Observações'!$C$9)+M4*'Programas e Observações'!$C$10) -> 259140.96 | AI4: =12*(J4*'Programas e Observações'!$D$8+K4*'Programas e Observações'!$D$9+L4*('Programas e Observações'!$D$8+'Programas e Observações'!$D$9)+M4*'Programas e Observações'!$D$10) -> 409078.08 | AJ4: 421 moradores pegam remédio de pressão ou diabetes de graça na Farmácia Popular | AK4: Sem o programa, gastariam pelo menos R$ 259 mil por ano
A5: 1100049 | B5: 110004 | C5: Cacoal | D5: RO | E5: 11002 | F5: Café | G5: 98280 | H5: =G5<'Programas e Observações'!$C$11 -> FALSE | I5: 3290 | J5: 1754 | K5: 214 | L5: 847 | M5: 156 | N5: 1116 | O5: 271 | P5: 7 | Q5: 215 | R5: =IF(G5>0,1000*I5/G5,0) -> 33.475783 | S5: =IF(G5>0,1000*J5/G5,0) -> 17.846968 | T5: =IF(G5>0,1000*K5/G5,0) -> 2.1774522 | U5: =IF(G5>0,1000*L5/G5,0) -> 8.6182336 | V5: =IF(G5>0,1000*M5/G5,0) -> 1.5873016 | W5: =IF(G5>0,1000*N5/G5,0) -> 11.355311 | X5: =IF(G5>0,1000*O5/G5,0) -> 2.7574278 | Y5: =SUMIFS($I$2:$I$5572,$E$2:$E$5572,E5) -> 5842 | Z5: =SUMIFS($J$2:$J$5572,$E$2:$E$5572,E5) -> 3287 | AA5: =SUMIFS($K$2:$K$5572,$E$2:$E$5572,E5) -> 380 | AB5: =SUMIFS($L$2:$L$5572,$E$2:$E$5572,E5) -> 1380 | AC5: =SUMIFS($M$2:$M$5572,$E$2:$E$5572,E5) -> 222 | AD5: =SUMIFS($N$2:$N$5572,$E$2:$E$5572,E5) -> 1947 | AE5: =SUMIFS($O$2:$O$5572,$E$2:$E$5572,E5) -> 442 | AF5: =SUMIFS($P$2:$P$5572,$E$2:$E$5572,E5) -> 14 | AG5: =IF(SUMIFS($G$2:$G$5572,$E$2:$E$5572,E5)>0,1000*Y5/SUMIFS($G$2:$G$5572,$E$2:$E$5572,E5),0) -> 31.456463 | AH5: =12*(J5*'Programas e Observações'!$C$8+K5*'Programas e Observações'!$C$9+L5*('Programas e Observações'!$C$8+'Programas e Observações'!$C$9)+M5*'Programas e Observações'!$C$10) -> 1139287.7 | AI5: =12*(J5*'Programas e Observações'!$D$8+K5*'Programas e Observações'!$D$9+L5*('Programas e Observações'!$D$8+'Programas e Observações'!$D$9)+M5*'Programas e Observações'!$D$10) -> 2099856.6 | AJ5: 2.815 moradores pegam remédio de pressão ou diabetes de graça na Farmácia Popular | AK5: Sem o programa, gastariam pelo menos R$ 1,1 milhões por ano
A6: 1100056 | B6: 110005 | C6: Cerejeiras | D6: RO | E6: 11006 | F6: Cone Sul | G6: 16966 | H6: =G6<'Programas e Observações'!$C$11 -> TRUE | I6: 387 | J6: 148 | K6: 48 | L6: 60 | M6: 1 | N6: 225 | O6: 37 | P6: 0 | R6: =IF(G6>0,1000*I6/G6,0) -> 22.810327 | S6: =IF(G6>0,1000*J6/G6,0) -> 8.723329 | T6: =IF(G6>0,1000*K6/G6,0) -> 2.8291878 | U6: =IF(G6>0,1000*L6/G6,0) -> 3.5364847 | V6: =IF(G6>0,1000*M6/G6,0) -> 0.058941412 | W6: =IF(G6>0,1000*N6/G6,0) -> 13.261818 | X6: =IF(G6>0,1000*O6/G6,0) -> 2.1808323 | Y6: =SUMIFS($I$2:$I$5572,$E$2:$E$5572,E6) -> 6176 | Z6: =SUMIFS($J$2:$J$5572,$E$2:$E$5572,E6) -> 3173 | AA6: =SUMIFS($K$2:$K$5572,$E$2:$E$5572,E6) -> 544 | AB6: =SUMIFS($L$2:$L$5572,$E$2:$E$5572,E6) -> 1434 | AC6: =SUMIFS($M$2:$M$5572,$E$2:$E$5572,E6) -> 238 | AD6: =SUMIFS($N$2:$N$5572,$E$2:$E$5572,E6) -> 1653 | AE6: =SUMIFS($O$2:$O$5572,$E$2:$E$5572,E6) -> 277 | AF6: =SUMIFS($P$2:$P$5572,$E$2:$E$5572,E6) -> 5 | AG6: =IF(SUMIFS($G$2:$G$5572,$E$2:$E$5572,E6)>0,1000*Y6/SUMIFS($G$2:$G$5572,$E$2:$E$5572,E6),0) -> 36.48889 | AH6: =12*(J6*'Programas e Observações'!$C$8+K6*'Programas e Observações'!$C$9+L6*('Programas e Observações'!$C$8+'Programas e Observações'!$C$9)+M6*'Programas e Observações'!$C$10) -> 96851.28 | AI6: =12*(J6*'Programas e Observações'!$D$8+K6*'Programas e Observações'!$D$9+L6*('Programas e Observações'!$D$8+'Programas e Observações'!$D$9)+M6*'Programas e Observações'!$D$10) -> 174003.48 | AJ6: 256 moradores pegam remédio de pressão ou diabetes de graça na Farmácia Popular | AK6: Sem o programa, gastariam pelo menos R$ 97 mil por ano
A7: 1100064 | B7: 110006 | C7: Colorado do Oeste | D7: RO | E7: 11006 | F7: Cone Sul | G7: 16508 | H7: =G7<'Programas e Observações'!$C$11 -> TRUE | I7: 882 | J7: 474 | K7: 79 | L7: 169 | M7: 22 | N7: 308 | O7: 36 | P7: 1 | R7: =IF(G7>0,1000*I7/G7,0) -> 53.428641 | S7: =IF(G7>0,1000*J7/G7,0) -> 28.713351 | T7: =IF(G7>0,1000*K7/G7,0) -> 4.7855585 | U7: =IF(G7>0,1000*L7/G7,0) -> 10.237461 | V7: =IF(G7>0,1000*M7/G7,0) -> 1.3326872 | W7: =IF(G7>0,1000*N7/G7,0) -> 18.657621 | X7: =IF(G7>0,1000*O7/G7,0) -> 2.1807608 | Y7: =SUMIFS($I$2:$I$5572,$E$2:$E$5572,E7) -> 6176 | Z7: =SUMIFS($J$2:$J$5572,$E$2:$E$5572,E7) -> 3173 | AA7: =SUMIFS($K$2:$K$5572,$E$2:$E$5572,E7) -> 544 | AB7: =SUMIFS($L$2:$L$5572,$E$2:$E$5572,E7) -> 1434 | AC7: =SUMIFS($M$2:$M$5572,$E$2:$E$5572,E7) -> 238 | AD7: =SUMIFS($N$2:$N$5572,$E$2:$E$5572,E7) -> 1653 | AE7: =SUMIFS($O$2:$O$5572,$E$2:$E$5572,E7) -> 277 | AF7: =SUMIFS($P$2:$P$5572,$E$2:$E$5572,E7) -> 5 | AG7: =IF(SUMIFS($G$2:$G$5572,$E$2:$E$5572,E7)>0,1000*Y7/SUMIFS($G$2:$G$5572,$E$2:$E$5572,E7),0) -> 36.48889 | AH7: =12*(J7*'Programas e Observações'!$C$8+K7*'Programas e Observações'!$C$9+L7*('Programas e Observações'!$C$8+'Programas e Observações'!$C$9)+M7*'Programas e Observações'!$C$10) -> 265631.16 | AI7: =12*(J7*'Programas e Observações'!$D$8+K7*'Programas e Observações'!$D$9+L7*('Programas e Observações'!$D$8+'Programas e Observações'!$D$9)+M7*'Programas e Observações'!$D$10) -> 502550.64 | AJ7: 722 moradores pegam remédio de pressão ou diabetes de graça na Farmácia Popular | AK7: Sem o programa, gastariam pelo menos R$ 266 mil por ano
A8: 1100072 | B8: 110007 | C8: Corumbiara | D8: RO | E8: 11006 | F8: Cone Sul | G8: 7968 | H8: =G8<'Programas e Observações'!$C$11 -> TRUE | I8: 555 | J8: 332 | K8: 43 | L8: 109 | M8: 3 | N8: 65 | O8: 13 | P8: 1 | R8: =IF(G8>0,1000*I8/G8,0) -> 69.653614 | S8: =IF(G8>0,1000*J8/G8,0) -> 41.666667 | T8: =IF(G8>0,1000*K8/G8,0) -> 5.3965863 | U8: =IF(G8>0,1000*L8/G8,0) -> 13.679719 | V8: =IF(G8>0,1000*M8/G8,0) -> 0.37650602 | W8: =IF(G8>0,1000*N8/G8,0) -> 8.1576305 | X8: =IF(G8>0,1000*O8/G8,0) -> 1.6315261 | Y8: =SUMIFS($I$2:$I$5572,$E$2:$E$5572,E8) -> 6176 | Z8: =SUMIFS($J$2:$J$5572,$E$2:$E$5572,E8) -> 3173 | AA8: =SUMIFS($K$2:$K$5572,$E$2:$E$5572,E8) -> 544 | AB8: =SUMIFS($L$2:$L$5572,$E$2:$E$5572,E8) -> 1434 | AC8: =SUMIFS($M$2:$M$5572,$E$2:$E$5572,E8) -> 238 | AD8: =SUMIFS($N$2:$N$5572,$E$2:$E$5572,E8) -> 1653 | AE8: =SUMIFS($O$2:$O$5572,$E$2:$E$5572,E8) -> 277 | AF8: =SUMIFS($P$2:$P$5572,$E$2:$E$5572,E8) -> 5 | AG8: =IF(SUMIFS($G$2:$G$5572,$E$2:$E$5572,E8)>0,1000*Y8/SUMIFS($G$2:$G$5572,$E$2:$E$5572,E8),0) -> 36.48889 | AH8: =12*(J8*'Programas e Observações'!$C$8+K8*'Programas e Observações'!$C$9+L8*('Programas e Observações'!$C$8+'Programas e Observações'!$C$9)+M8*'Programas e Observações'!$C$10) -> 166593.24 | AI8: =12*(J8*'Programas e Observações'!$D$8+K8*'Programas e Observações'!$D$9+L8*('Programas e Observações'!$D$8+'Programas e Observações'!$D$9)+M8*'Programas e Observações'!$D$10) -> 328520.52 | AJ8: 484 moradores pegam remédio de pressão ou diabetes de graça na Farmácia Popular | AK8: Sem o programa, gastariam pelo menos R$ 167 mil por ano
A9: 1100080 | B9: 110008 | C9: Costa Marques | D9: RO | E9: 11007 | F9: Vale do Guaporé | G9: 13510 | H9: =G9<'Programas e Observações'!$C$11 -> TRUE | I9: 301 | J9: 203 | K9: 25 | L9: 45 | M9: 0 | N9: 57 | O9: 17 | P9: 1 | R9: =IF(G9>0,1000*I9/G9,0) -> 22.279793 | S9: =IF(G9>0,1000*J9/G9,0) -> 15.025907 | T9: =IF(G9>0,1000*K9/G9,0) -> 1.8504811 | U9: =IF(G9>0,1000*L9/G9,0) -> 3.330866 | V9: =IF(G9>0,1000*M9/G9,0) -> 0 | W9: =IF(G9>0,1000*N9/G9,0) -> 4.219097 | X9: =IF(G9>0,1000*O9/G9,0) -> 1.2583272 | Y9: =SUMIFS($I$2:$I$5572,$E$2:$E$5572,E9) -> 554 | Z9: =SUMIFS($J$2:$J$5572,$E$2:$E$5572,E9) -> 380 | AA9: =SUMIFS($K$2:$K$5572,$E$2:$E$5572,E9) -> 42 | AB9: =SUMIFS($L$2:$L$5572,$E$2:$E$5572,E9) -> 103 | AC9: =SUMIFS($M$2:$M$5572,$E$2:$E$5572,E9) -> 0 | AD9: =SUMIFS($N$2:$N$5572,$E$2:$E$5572,E9) -> 284 | AE9: =SUMIFS($O$2:$O$5572,$E$2:$E$5572,E9) -> 56 | AF9: =SUMIFS($P$2:$P$5572,$E$2:$E$5572,E9) -> 2 | AG9: =IF(SUMIFS($G$2:$G$5572,$E$2:$E$5572,E9)>0,1000*Y9/SUMIFS($G$2:$G$5572,$E$2:$E$5572,E9),0) -> 12.581759 | AH9: =12*(J9*'Programas e Observações'!$C$8+K9*'Programas e Observações'!$C$9+L9*('Programas e Observações'!$C$8+'Programas e Observações'!$C$9)+M9*'Programas e Observações'!$C$10) -> 84910.8 | AI9: =12*(J9*'Programas e Observações'!$D$8+K9*'Programas e Observações'!$D$9+L9*('Programas e Observações'!$D$8+'Programas e Observações'!$D$9)+M9*'Programas e Observações'!$D$10) -> 175613.52 | AJ9: 273 moradores pegam remédio de pressão ou diabetes de graça na Farmácia Popular | AK9: Sem o programa, gastariam pelo menos R$ 85 mil por ano
A10: 1100098 | B10: 110009 | C10: Espigão D'Oeste | D10: RO | E10: 11002 | F10: Café | G10: 32842 | H10: =G10<'Programas e Observações'!$C$11 -> FALSE | I10: 347 | J10: 237 | K10: 12 | L10: 45 | M10: 3 | N10: 280 | O10: 59 | P10: 2 | R10: =IF(G10>0,1000*I10/G10,0) -> 10.565739 | S10: =IF(G10>0,1000*J10/G10,0) -> 7.2163693 | T10: =IF(G10>0,1000*K10/G10,0) -> 0.36538579 | U10: =IF(G10>0,1000*L10/G10,0) -> 1.3701967 | V10: =IF(G10>0,1000*M10/G10,0) -> 0.091346447 | W10: =IF(G10>0,1000*N10/G10,0) -> 8.5256684 | X10: =IF(G10>0,1000*O10/G10,0) -> 1.7964801 | Y10: =SUMIFS($I$2:$I$5572,$E$2:$E$5572,E10) -> 5842 | Z10: =SUMIFS($J$2:$J$5572,$E$2:$E$5572,E10) -> 3287 | AA10: =SUMIFS($K$2:$K$5572,$E$2:$E$5572,E10) -> 380 | AB10: =SUMIFS($L$2:$L$5572,$E$2:$E$5572,E10) -> 1380 | AC10: =SUMIFS($M$2:$M$5572,$E$2:$E$5572,E10) -> 222 | AD10: =SUMIFS($N$2:$N$5572,$E$2:$E$5572,E10) -> 1947 | AE10: =SUMIFS($O$2:$O$5572,$E$2:$E$5572,E10) -> 442 | AF10: =SUMIFS($P$2:$P$5572,$E$2:$E$5572,E10) -> 14 | AG10: =IF(SUMIFS($G$2:$G$5572,$E$2:$E$5572,E10)>0,1000*Y10/SUMIFS($G$2:$G$5572,$E$2:$E$5572,E10),0) -> 31.456463 | AH10: =12*(J10*'Programas e Observações'!$C$8+K10*'Programas e Observações'!$C$9+L10*('Programas e Observações'!$C$8+'Programas e Observações'!$C$9)+M10*'Programas e Observações'!$C$10) -> 86622.84 | AI10: =12*(J10*'Programas e Observações'!$D$8+K10*'Programas e Observações'!$D$9+L10*('Programas e Observações'!$D$8+'Programas e Observações'!$D$9)+M10*'Programas e Observações'!$D$10) -> 189315.36 | AJ10: 294 moradores pegam remédio de pressão ou diabetes de graça na Farmácia Popular | AK10: Sem o programa, gastariam pelo menos R$ 87 mil por ano
A11: 1100106 | B11: 110010 | C11: Guajará-Mirim | D11: RO | E11: 11004 | F11: Madeira-Mamoré | G11: 43594 | H11: =G11<'Programas e Observações'!$C$11 -> FALSE | I11: 887 | J11: 421 | K11: 71 | L11: 228 | M11: 7 | N11: 130 | O11: 53 | P11: 2 | R11: =IF(G11>0,1000*I11/G11,0) -> 20.346837 | S11: =IF(G11>0,1000*J11/G11,0) -> 9.6572923 | T11: =IF(G11>0,1000*K11/G11,0) -> 1.6286645 | U11: =IF(G11>0,1000*L11/G11,0) -> 5.2300775 | V11: =IF(G11>0,1000*M11/G11,0) -> 0.16057256 | W11: =IF(G11>0,1000*N11/G11,0) -> 2.9820618 | X11: =IF(G11>0,1000*O11/G11,0) -> 1.2157636 | Y11: =SUMIFS($I$2:$I$5572,$E$2:$E$5572,E11) -> 6894 | Z11: =SUMIFS($J$2:$J$5572,$E$2:$E$5572,E11) -> 1916 | AA11: =SUMIFS($K$2:$K$5572,$E$2:$E$5572,E11) -> 1016 | AB11: =SUMIFS($L$2:$L$5572,$E$2:$E$5572,E11) -> 1376 | AC11: =SUMIFS($M$2:$M$5572,$E$2:$E$5572,E11) -> 263 | AD11: =SUMIFS($N$2:$N$5572,$E$2:$E$5572,E11) -> 5769 | AE11: =SUMIFS($O$2:$O$5572,$E$2:$E$5572,E11) -> 1523 | AF11: =SUMIFS($P$2:$P$5572,$E$2:$E$5572,E11) -> 22 | AG11: =IF(SUMIFS($G$2:$G$5572,$E$2:$E$5572,E11)>0,1000*Y11/SUMIFS($G$2:$G$5572,$E$2:$E$5572,E11),0) -> 11.056139 | AH11: =12*(J11*'Programas e Observações'!$C$8+K11*'Programas e Observações'!$C$9+L11*('Programas e Observações'!$C$8+'Programas e Observações'!$C$9)+M11*'Programas e Observações'!$C$10) -> 284892.96 | AI11: =12*(J11*'Programas e Observações'!$D$8+K11*'Programas e Observações'!$D$9+L11*('Programas e Observações'!$D$8+'Programas e Observações'!$D$9)+M11*'Programas e Observações'!$D$10) -> 524857.68 | AJ11: 720 moradores pegam remédio de pressão ou diabetes de graça na Farmácia Popular | AK11: Sem o programa, gastariam pelo menos R$ 285 mil por ano
A12: 1100114 | B12: 110011 | C12: Jaru | D12: RO | E12: 11003 | F12: Central | G12: 55682 | H12: =G12<'Programas e Observações'!$C$11 -> FALSE | I12: 684 | J12: 251 | K12: 61 | L12: 126 | M12: 4 | N12: 572 | O12: 124 | P12: 4 | Q12: 75 | R12: =IF(G12>0,1000*I12/G12,0) -> 12.284042 | S12: =IF(G12>0,1000*J12/G12,0) -> 4.5077404 | T12: =IF(G12>0,1000*K12/G12,0) -> 1.0955066 | U12: =IF(G12>0,1000*L12/G12,0) -> 2.2628498 | V12: =IF(G12>0,1000*M12/G12,0) -> 0.0718365 | W12: =IF(G12>0,1000*N12/G12,0) -> 10.27262 | X12: =IF(G12>0,1000*O12/G12,0) -> 2.2269315 | Y12: =SUMIFS($I$2:$I$5572,$E$2:$E$5572,E12) -> 5999 | Z12: =SUMIFS($J$2:$J$5572,$E$2:$E$5572,E12) -> 2842 | AA12: =SUMIFS($K$2:$K$5572,$E$2:$E$5572,E12) -> 444 | AB12: =SUMIFS($L$2:$L$5572,$E$2:$E$5572,E12) -> 1118 | AC12: =SUMIFS($M$2:$M$5572,$E$2:$E$5572,E12) -> 101 | AD12: =SUMIFS($N$2:$N$5572,$E$2:$E$5572,E12) -> 3467 | AE12: =SUMIFS($O$2:$O$5572,$E$2:$E$5572,E12) -> 774 | AF12: =SUMIFS($P$2:$P$5572,$E$2:$E$5572,E12) -> 18 | AG12: =IF(SUMIFS($G$2:$G$5572,$E$2:$E$5572,E12)>0,1000*Y12/SUMIFS($G$2:$G$5572,$E$2:$E$5572,E12),0) -> 16.909213 | AH12: =12*(J12*'Programas e Observações'!$C$8+K12*'Programas e Observações'!$C$9+L12*('Programas e Observações'!$C$8+'Programas e Observações'!$C$9)+M12*'Programas e Observações'!$C$10) -> 172239.12 | AI12: =12*(J12*'Programas e Observações'!$D$8+K12*'Programas e Observações'!$D$9+L12*('Programas e Observações'!$D$8+'Programas e Observações'!$D$9)+M12*'Programas e Observações'!$D$10) -> 311919.72 | AJ12: 438 moradores pegam remédio de pressão ou diabetes de graça na Farmácia Popular | AK12: Sem o programa, gastariam pelo menos R$ 172 mil por ano
A13: 1100122 | B13: 110012 | C13: Ji-Paraná | D13: RO | E13: 11003 | F13: Central | G13: 140101 | H13: =G13<'Programas e Observações'!$C$11 -> FALSE | I13: 1907 | J13: 713 | K13: 166 | L13: 276 | M13: 27 | N13: 1369 | O13: 280 | P13: 4 | Q13: 373 | R13: =IF(G13>0,1000*I13/G13,0) -> 13.611609 | S13: =IF(G13>0,1000*J13/G13,0) -> 5.0891857 | T13: =IF(G13>0,1000*K13/G13,0) -> 1.1848595 | U13: =IF(G13>0,1000*L13/G13,0) -> 1.9700074 | V13: =IF(G13>0,1000*M13/G13,0) -> 0.19271811 | W13: =IF(G13>0,1000*N13/G13,0) -> 9.771522 | X13: =IF(G13>0,1000*O13/G13,0) -> 1.9985582 | Y13: =SUMIFS($I$2:$I$5572,$E$2:$E$5572,E13) -> 5999 | Z13: =SUMIFS($J$2:$J$5572,$E$2:$E$5572,E13) -> 2842 | AA13: =SUMIFS($K$2:$K$5572,$E$2:$E$5572,E13) -> 444 | AB13: =SUMIFS($L$2:$L$5572,$E$2:$E$5572,E13) -> 1118 | AC13: =SUMIFS($M$2:$M$5572,$E$2:$E$5572,E13) -> 101 | AD13: =SUMIFS($N$2:$N$5572,$E$2:$E$5572,E13) -> 3467 | AE13: =SUMIFS($O$2:$O$5572,$E$2:$E$5572,E13) -> 774 | AF13: =SUMIFS($P$2:$P$5572,$E$2:$E$5572,E13) -> 18 | AG13: =IF(SUMIFS($G$2:$G$5572,$E$2:$E$5572,E13)>0,1000*Y13/SUMIFS($G$2:$G$5572,$E$2:$E$5572,E13),0) -> 16.909213 | AH13: =12*(J13*'Programas e Observações'!$C$8+K13*'Programas e Observações'!$C$9+L13*('Programas e Observações'!$C$8+'Programas e Observações'!$C$9)+M13*'Programas e Observações'!$C$10) -> 435806.76 | AI13: =12*(J13*'Programas e Observações'!$D$8+K13*'Programas e Observações'!$D$9+L13*('Programas e Observações'!$D$8+'Programas e Observações'!$D$9)+M13*'Programas e Observações'!$D$10) -> 801423.48 | AJ13: 1.155 moradores pegam remédio de pressão ou diabetes de graça na Farmácia Popular | AK13: Sem o programa, gastariam pelo menos R$ 436 mil por ano
A14: 1100130 | B14: 110013 | C14: Machadinho D'Oeste | D14: RO | E14: 11001 | F14: Vale do Jamari | G14: 34149 | H14: =G14<'Programas e Observações'!$C$11 -> FALSE | I14: 333 | J14: 187 | K14: 19 | L14: 30 | M14: 5 | N14: 226 | O14: 51 | P14: 3 | R14: =IF(G14>0,1000*I14/G14,0) -> 9.7513836 | S14: =IF(G14>0,1000*J14/G14,0) -> 5.4760022 | T14: =IF(G14>0,1000*K14/G14,0) -> 0.55638525 | U14: =IF(G14>0,1000*L14/G14,0) -> 0.87850303 | V14: =IF(G14>0,1000*M14/G14,0) -> 0.14641717 | W14: =IF(G14>0,1000*N14/G14,0) -> 6.6180562 | X14: =IF(G14>0,1000*O14/G14,0) -> 1.4934552 | Y14: =SUMIFS($I$2:$I$5572,$E$2:$E$5572,E14) -> 3070 | Z14: =SUMIFS($J$2:$J$5572,$E$2:$E$5572,E14) -> 1523 | AA14: =SUMIFS($K$2:$K$5572,$E$2:$E$5572,E14) -> 232 | AB14: =SUMIFS($L$2:$L$5572,$E$2:$E$5572,E14) -> 477 | AC14: =SUMIFS($M$2:$M$5572,$E$2:$E$5572,E14) -> 83 | AD14: =SUMIFS($N$2:$N$5572,$E$2:$E$5572,E14) -> 2055 | AE14: =SUMIFS($O$2:$O$5572,$E$2:$E$5572,E14) -> 401 | AF14: =SUMIFS($P$2:$P$5572,$E$2:$E$5572,E14) -> 13 | AG14: =IF(SUMIFS($G$2:$G$5572,$E$2:$E$5572,E14)>0,1000*Y14/SUMIFS($G$2:$G$5572,$E$2:$E$5572,E14),0) -> 12.973622 | AH14: =12*(J14*'Programas e Observações'!$C$8+K14*'Programas e Observações'!$C$9+L14*('Programas e Observações'!$C$8+'Programas e Observações'!$C$9)+M14*'Programas e Observações'!$C$10) -> 70693.2 | AI14: =12*(J14*'Programas e Observações'!$D$8+K14*'Programas e Observações'!$D$9+L14*('Programas e Observações'!$D$8+'Programas e Observações'!$D$9)+M14*'Programas e Observações'!$D$10) -> 149864.88 | AJ14: 236 moradores pegam remédio de pressão ou diabetes de graça na Farmácia Popular | AK14: Sem o programa, gastariam pelo menos R$ 71 mil por ano
A15: 1100148 | B15: 110014 | C15: Nova Brasilândia D'Oeste | D15: RO | E15: 11005 | F15: Zona da Mata | G15: 16374 | H15: =G15<'Programas e Observações'!$C$11 -> TRUE | I15: 212 | J15: 96 | K15: 30 | L15: 37 | M15: 4 | N15: 218 | O15: 37 | P15: 1 | R15: =IF(G15>0,1000*I15/G15,0) -> 12.947356 | S15: =IF(G15>0,1000*J15/G15,0) -> 5.8629535 | T15: =IF(G15>0,1000*K15/G15,0) -> 1.832173 | U15: =IF(G15>0,1000*L15/G15,0) -> 2.25968 | V15: =IF(G15>0,1000*M15/G15,0) -> 0.24428973 | W15: =IF(G15>0,1000*N15/G15,0) -> 13.31379 | X15: =IF(G15>0,1000*O15/G15,0) -> 2.25968 | Y15: =SUMIFS($I$2:$I$5572,$E$2:$E$5572,E15) -> 3387 | Z15: =SUMIFS($J$2:$J$5572,$E$2:$E$5572,E15) -> 1912 | AA15: =SUMIFS($K$2:$K$5572,$E$2:$E$5572,E15) -> 196 | AB15: =SUMIFS($L$2:$L$5572,$E$2:$E$5572,E15) -> 835 | AC15: =SUMIFS($M$2:$M$5572,$E$2:$E$5572,E15) -> 38 | AD15: =SUMIFS($N$2:$N$5572,$E$2:$E$5572,E15) -> 1751 | AE15: =SUMIFS($O$2:$O$5572,$E$2:$E$5572,E15) -> 314 | AF15: =SUMIFS($P$2:$P$5572,$E$2:$E$5572,E15) -> 7 | AG15: =IF(SUMIFS($G$2:$G$5572,$E$2:$E$5572,E15)>0,1000*Y15/SUMIFS($G$2:$G$5572,$E$2:$E$5572,E15),0) -> 24.545613 | AH15: =12*(J15*'Programas e Observações'!$C$8+K15*'Programas e Observações'!$C$9+L15*('Programas e Observações'!$C$8+'Programas e Observações'!$C$9)+M15*'Programas e Observações'!$C$10) -> 62652.72 | AI15: =12*(J15*'Programas e Observações'!$D$8+K15*'Programas e Observações'!$D$9+L15*('Programas e Observações'!$D$8+'Programas e Observações'!$D$9)+M15*'Programas e Observações'!$D$10) -> 111989.16 | AJ15: 163 moradores pegam remédio de pressão ou diabetes de graça na Farmácia Popular | AK15: Sem o programa, gastariam pelo menos R$ 63 mil por ano
A16: 1100155 | B16: 110015 | C16: Ouro Preto do Oeste | D16: RO | E16: 11003 | F16: Central | G16: 38684 | H16: =G16<'Programas e Observações'!$C$11 -> FALSE | I16: 983 | J16: 474 | K16: 76 | L16: 235 | M16: 13 | N16: 293 | O16: 112 | P16: 3 | R16: =IF(G16>0,1000*I16/G16,0) -> 25.411023 | S16: =IF(G16>0,1000*J16/G16,0) -> 12.253128 | T16: =IF(G16>0,1000*K16/G16,0) -> 1.9646365 | U16: =IF(G16>0,1000*L16/G16,0) -> 6.074863 | V16: =IF(G16>0,1000*M16/G16,0) -> 0.33605625 | W16: =IF(G16>0,1000*N16/G16,0) -> 7.5741909 | X16: =IF(G16>0,1000*O16/G16,0) -> 2.8952539 | Y16: =SUMIFS($I$2:$I$5572,$E$2:$E$5572,E16) -> 5999 | Z16: =SUMIFS($J$2:$J$5572,$E$2:$E$5572,E16) -> 2842 | AA16: =SUMIFS($K$2:$K$5572,$E$2:$E$5572,E16) -> 444 | AB16: =SUMIFS($L$2:$L$5572,$E$2:$E$5572,E16) -> 1118 | AC16: =SUMIFS($M$2:$M$5572,$E$2:$E$5572,E16) -> 101 | AD16: =SUMIFS($N$2:$N$5572,$E$2:$E$5572,E16) -> 3467 | AE16: =SUMIFS($O$2:$O$5572,$E$2:$E$5572,E16) -> 774 | AF16: =SUMIFS($P$2:$P$5572,$E$2:$E$5572,E16) -> 18 | AG16: =IF(SUMIFS($G$2:$G$5572,$E$2:$E$5572,E16)>0,1000*Y16/SUMIFS($G$2:$G$5572,$E$2:$E$5572,E16),0) -> 16.909213 | AH16: =12*(J16*'Programas e Observações'!$C$8+K16*'Programas e Observações'!$C$9+L16*('Programas e Observações'!$C$8+'Programas e Observações'!$C$9)+M16*'Programas e Observações'!$C$10) -> 306085.44 | AI16: =12*(J16*'Programas e Observações'!$D$8+K16*'Programas e Observações'!$D$9+L16*('Programas e Observações'!$D$8+'Programas e Observações'!$D$9)+M16*'Programas e Observações'!$D$10) -> 567973.44 | AJ16: 785 moradores pegam remédio de pressão ou diabetes de graça na Farmácia Popular | AK16: Sem o programa, gastariam pelo menos R$ 306 mil por ano
A17: 1100189 | B17: 110018 | C17: Pimenta Bueno | D17: RO | E17: 11002 | F17: Café | G17: 39220 | H17: =G17<'Programas e Observações'!$C$11 -> FALSE | I17: 1823 | J17: 982 | K17: 147 | L17: 453 | M17: 55 | N17: 371 | O17: 65 | P17: 2 | R17: =IF(G17>0,1000*I17/G17,0) -> 46.481387 | S17: =IF(G17>0,1000*J17/G17,0) -> 25.038246 | T17: =IF(G17>0,1000*K17/G17,0) -> 3.7480877 | U17: =IF(G17>0,1000*L17/G17,0) -> 11.550229 | V17: =IF(G17>0,1000*M17/G17,0) -> 1.4023457 | W17: =IF(G17>0,1000*N17/G17,0) -> 9.4594595 | X17: =IF(G17>0,1000*O17/G17,0) -> 1.6573177 | Y17: =SUMIFS($I$2:$I$5572,$E$2:$E$5572,E17) -> 5842 | Z17: =SUMIFS($J$2:$J$5572,$E$2:$E$5572,E17) -> 3287 | AA17: =SUMIFS($K$2:$K$5572,$E$2:$E$5572,E17) -> 380 | AB17: =SUMIFS($L$2:$L$5572,$E$2:$E$5572,E17) -> 1380 | AC17: =SUMIFS($M$2:$M$5572,$E$2:$E$5572,E17) -> 222 | AD17: =SUMIFS($N$2:$N$5572,$E$2:$E$5572,E17) -> 1947 | AE17: =SUMIFS($O$2:$O$5572,$E$2:$E$5572,E17) -> 442 | AF17: =SUMIFS($P$2:$P$5572,$E$2:$E$5572,E17) -> 14 | AG17: =IF(SUMIFS($G$2:$G$5572,$E$2:$E$5572,E17)>0,1000*Y17/SUMIFS($G$2:$G$5572,$E$2:$E$5572,E17),0) -> 31.456463 | AH17: =12*(J17*'Programas e Observações'!$C$8+K17*'Programas e Observações'!$C$9+L17*('Programas e Observações'!$C$8+'Programas e Observações'!$C$9)+M17*'Programas e Observações'!$C$10) -> 619631.4 | AI17: =12*(J17*'Programas e Observações'!$D$8+K17*'Programas e Observações'!$D$9+L17*('Programas e Observações'!$D$8+'Programas e Observações'!$D$9)+M17*'Programas e Observações'!$D$10) -> 1149460.2 | AJ17: 1.582 moradores pegam remédio de pressão ou diabetes de graça na Farmácia Popular | AK17: Sem o programa, gastariam pelo menos R$ 620 mil por ano
A18: 1100205 | B18: 110020 | C18: Porto Velho | D18: RO | E18: 11004 | F18: Madeira-Mamoré | G18: 517709 | H18: =G18<'Programas e Observações'!$C$11 -> FALSE | I18: 5535 | J18: 1289 | K18: 893 | L18: 1061 | M18: 234 | N18: 5304 | O18: 1367 | P18: 19 | Q18: 2756 | R18: =IF(G18>0,1000*I18/G18,0) -> 10.691334 | S18: =IF(G18>0,1000*J18/G18,0) -> 2.4898157 | T18: =IF(G18>0,1000*K18/G18,0) -> 1.7249072 | U18: =IF(G18>0,1000*L18/G18,0) -> 2.0494139 | V18: =IF(G18>0,1000*M18/G18,0) -> 0.45199137 | W18: =IF(G18>0,1000*N18/G18,0) -> 10.245138 | X18: =IF(G18>0,1000*O18/G18,0) -> 2.6404795 | Y18: =SUMIFS($I$2:$I$5572,$E$2:$E$5572,E18) -> 6894 | Z18: =SUMIFS($J$2:$J$5572,$E$2:$E$5572,E18) -> 1916 | AA18: =SUMIFS($K$2:$K$5572,$E$2:$E$5572,E18) -> 1016 | AB18: =SUMIFS($L$2:$L$5572,$E$2:$E$5572,E18) -> 1376 | AC18: =SUMIFS($M$2:$M$5572,$E$2:$E$5572,E18) -> 263 | AD18: =SUMIFS($N$2:$N$5572,$E$2:$E$5572,E18) -> 5769 | AE18: =SUMIFS($O$2:$O$5572,$E$2:$E$5572,E18) -> 1523 | AF18: =SUMIFS($P$2:$P$5572,$E$2:$E$5572,E18) -> 22 | AG18: =IF(SUMIFS($G$2:$G$5572,$E$2:$E$5572,E18)>0,1000*Y18/SUMIFS($G$2:$G$5572,$E$2:$E$5572,E18),0) -> 11.056139 | AH18: =12*(J18*'Programas e Observações'!$C$8+K18*'Programas e Observações'!$C$9+L18*('Programas e Observações'!$C$8+'Programas e Observações'!$C$9)+M18*'Programas e Observações'!$C$10) -> 1585461.1 | AI18: =12*(J18*'Programas e Observações'!$D$8+K18*'Programas e Observações'!$D$9+L18*('Programas e Observações'!$D$8+'Programas e Observações'!$D$9)+M18*'Programas e Observações'!$D$10) -> 2476163 | AJ18: 3.243 moradores pegam remédio de pressão ou diabetes de graça na Farmácia Popular | AK18: Sem o programa, gastariam pelo menos R$ 1,6 milhões por ano
A19: 1100254 | B19: 110025 | C19: Presidente Médici | D19: RO | E19: 11003 | F19: Central | G19: 20443 | H19: =G19<'Programas e Observações'!$C$11 -> FALSE | I19: 506 | J19: 250 | K19: 31 | L19: 89 | M19: 17 | N19: 284 | O19: 49 | P19: 3 | R19: =IF(G19>0,1000*I19/G19,0) -> 24.751749 | S19: =IF(G19>0,1000*J19/G19,0) -> 12.229125 | T19: =IF(G19>0,1000*K19/G19,0) -> 1.5164115 | U19: =IF(G19>0,1000*L19/G19,0) -> 4.3535685 | V19: =IF(G19>0,1000*M19/G19,0) -> 0.83158049 | W19: =IF(G19>0,1000*N19/G19,0) -> 13.892286 | X19: =IF(G19>0,1000*O19/G19,0) -> 2.3969085 | Y19: =SUMIFS($I$2:$I$5572,$E$2:$E$5572,E19) -> 5999 | Z19: =SUMIFS($J$2:$J$5572,$E$2:$E$5572,E19) -> 2842 | AA19: =SUMIFS($K$2:$K$5572,$E$2:$E$5572,E19) -> 444 | AB19: =SUMIFS($L$2:$L$5572,$E$2:$E$5572,E19) -> 1118 | AC19: =SUMIFS($M$2:$M$5572,$E$2:$E$5572,E19) -> 101 | AD19: =SUMIFS($N$2:$N$5572,$E$2:$E$5572,E19) -> 3467 | AE19: =SUMIFS($O$2:$O$5572,$E$2:$E$5572,E19) -> 774 | AF19: =SUMIFS($P$2:$P$5572,$E$2:$E$5572,E19) -> 18 | AG19: =IF(SUMIFS($G$2:$G$5572,$E$2:$E$5572,E19)>0,1000*Y19/SUMIFS($G$2:$G$5572,$E$2:$E$5572,E19),0) -> 16.909213 | AH19: =12*(J19*'Programas e Observações'!$C$8+K19*'Programas e Observações'!$C$9+L19*('Programas e Observações'!$C$8+'Programas e Observações'!$C$9)+M19*'Programas e Observações'!$C$10) -> 137417.16 | AI19: =12*(J19*'Programas e Observações'!$D$8+K19*'Programas e Observações'!$D$9+L19*('Programas e Observações'!$D$8+'Programas e Observações'!$D$9)+M19*'Programas e Observações'!$D$10) -> 262169.88 | AJ19: 370 moradores pegam remédio de pressão ou diabetes de graça na Farmácia Popular | AK19: Sem o programa, gastariam pelo menos R$ 137 mil por ano
A20: 1100262 | B20: 110026 | C20: Rio Crespo | D20: RO | E20: 11001 | F20: Vale do Jamari | G20: 3767 | H20: =G20<'Programas e Observações'!$C$11 -> TRUE | I20: 12 | J20: 7 | K20: 0 | L20: 0 | M20: 0 | N20: 36 | O20: 5 | P20: 0 | R20: =IF(G20>0,1000*I20/G20,0) -> 3.1855588 | S20: =IF(G20>0,1000*J20/G20,0) -> 1.8582426 | T20: =IF(G20>0,1000*K20/G20,0) -> 0 | U20: =IF(G20>0,1000*L20/G20,0) -> 0 | V20: =IF(G20>0,1000*M20/G20,0) -> 0 | W20: =IF(G20>0,1000*N20/G20,0) -> 9.5566764 | X20: =IF(G20>0,1000*O20/G20,0) -> 1.3273162 | Y20: =SUMIFS($I$2:$I$5572,$E$2:$E$5572,E20) -> 3070 | Z20: =SUMIFS($J$2:$J$5572,$E$2:$E$5572,E20) -> 1523 | AA20: =SUMIFS($K$2:$K$5572,$E$2:$E$5572,E20) -> 232 | AB20: =SUMIFS($L$2:$L$5572,$E$2:$E$5572,E20) -> 477 | AC20: =SUMIFS($M$2:$M$5572,$E$2:$E$5572,E20) -> 83 | AD20: =SUMIFS($N$2:$N$5572,$E$2:$E$5572,E20) -> 2055 | AE20: =SUMIFS($O$2:$O$5572,$E$2:$E$5572,E20) -> 401 | AF20: =SUMIFS($P$2:$P$5572,$E$2:$E$5572,E20) -> 13 | AG20: =IF(SUMIFS($G$2:$G$5572,$E$2:$E$5572,E20)>0,1000*Y20/SUMIFS($G$2:$G$5572,$E$2:$E$5572,E20),0) -> 12.973622 | AH20: =12*(J20*'Programas e Observações'!$C$8+K20*'Programas e Observações'!$C$9+L20*('Programas e Observações'!$C$8+'Programas e Observações'!$C$9)+M20*'Programas e Observações'!$C$10) -> 1390.2 | AI20: =12*(J20*'Programas e Observações'!$D$8+K20*'Programas e Observações'!$D$9+L20*('Programas e Observações'!$D$8+'Programas e Observações'!$D$9)+M20*'Programas e Observações'!$D$10) -> 3907.68 | AJ20: 7 moradores pegam remédio de pressão ou diabetes de graça na Farmácia Popular | AK20: Sem o programa, gastariam pelo menos R$ 1 mil por ano
A21: 1100288 | B21: 110028 | C21: Rolim de Moura | D21: RO | E21: 11005 | F21: Zona da Mata | G21: 62959 | H21: =G21<'Programas e Observações'!$C$11 -> FALSE | I21: 1635 | J21: 874 | K21: 66 | L21: 509 | M21: 7 | N21: 697 | O21: 128 | P21: 3 | Q21: 126 | R21: =IF(G21>0,1000*I21/G21,0) -> 25.969282 | S21: =IF(G21>0,1000*J21/G21,0) -> 13.88205 | T21: =IF(G21>0,1000*K21/G21,0) -> 1.0483013 | U21: =IF(G21>0,1000*L21/G21,0) -> 8.0846265 | V21: =IF(G21>0,1000*M21/G21,0) -> 0.11118347 | W21: =IF(G21>0,1000*N21/G21,0) -> 11.070697 | X21: =IF(G21>0,1000*O21/G21,0) -> 2.0330691 | Y21: =SUMIFS($I$2:$I$5572,$E$2:$E$5572,E21) -> 3387 | Z21: =SUMIFS($J$2:$J$5572,$E$2:$E$5572,E21) -> 1912 | AA21: =SUMIFS($K$2:$K$5572,$E$2:$E$5572,E21) -> 196 | AB21: =SUMIFS($L$2:$L$5572,$E$2:$E$5572,E21) -> 835 | AC21: =SUMIFS($M$2:$M$5572,$E$2:$E$5572,E21) -> 38 | AD21: =SUMIFS($N$2:$N$5572,$E$2:$E$5572,E21) -> 1751 | AE21: =SUMIFS($O$2:$O$5572,$E$2:$E$5572,E21) -> 314 | AF21: =SUMIFS($P$2:$P$5572,$E$2:$E$5572,E21) -> 7 | AG21: =IF(SUMIFS($G$2:$G$5572,$E$2:$E$5572,E21)>0,1000*Y21/SUMIFS($G$2:$G$5572,$E$2:$E$5572,E21),0) -> 24.545613 | AH21: =12*(J21*'Programas e Observações'!$C$8+K21*'Programas e Observações'!$C$9+L21*('Programas e Observações'!$C$8+'Programas e Observações'!$C$9)+M21*'Programas e Observações'!$C$10) -> 571259.76 | AI21: =12*(J21*'Programas e Observações'!$D$8+K21*'Programas e Observações'!$D$9+L21*('Programas e Observações'!$D$8+'Programas e Observações'!$D$9)+M21*'Programas e Observações'!$D$10) -> 1081161.8 | AJ21: 1.449 moradores pegam remédio de pressão ou diabetes de graça na Farmácia Popular | AK21: Sem o programa, gastariam pelo menos R$ 571 mil por ano
A22: 1100296 | B22: 110029 | C22: Santa Luzia D'Oeste | D22: RO | E22: 11005 | F22: Zona da Mata | G22: 7837 | H22: =G22<'Programas e Observações'!$C$11 -> TRUE | I22: 271 | J22: 153 | K22: 16 | L22: 49 | M22: 3 | N22: 131 | O22: 22 | P22: 0 | R22: =IF(G22>0,1000*I22/G22,0) -> 34.579558 | S22: =IF(G22>0,1000*J22/G22,0) -> 19.522777 | T22: =IF(G22>0,1000*K22/G22,0) -> 2.0415976 | U22: =IF(G22>0,1000*L22/G22,0) -> 6.2523925 | V22: =IF(G22>0,1000*M22/G22,0) -> 0.38279954 | W22: =IF(G22>0,1000*N22/G22,0) -> 16.71558 | X22: =IF(G22>0,1000*O22/G22,0) -> 2.8071966 | Y22: =SUMIFS($I$2:$I$5572,$E$2:$E$5572,E22) -> 3387 | Z22: =SUMIFS($J$2:$J$5572,$E$2:$E$5572,E22) -> 1912 | AA22: =SUMIFS($K$2:$K$5572,$E$2:$E$5572,E22) -> 196 | AB22: =SUMIFS($L$2:$L$5572,$E$2:$E$5572,E22) -> 835 | AC22: =SUMIFS($M$2:$M$5572,$E$2:$E$5572,E22) -> 38 | AD22: =SUMIFS($N$2:$N$5572,$E$2:$E$5572,E22) -> 1751 | AE22: =SUMIFS($O$2:$O$5572,$E$2:$E$5572,E22) -> 314 | AF22: =SUMIFS($P$2:$P$5572,$E$2:$E$5572,E22) -> 7 | AG22: =IF(SUMIFS($G$2:$G$5572,$E$2:$E$5572,E22)>0,1000*Y22/SUMIFS($G$2:$G$5572,$E$2:$E$5572,E22),0) -> 24.545613 | AH22: =12*(J22*'Programas e Observações'!$C$8+K22*'Programas e Observações'!$C$9+L22*('Programas e Observações'!$C$8+'Programas e Observações'!$C$9)+M22*'Programas e Observações'!$C$10) -> 74810.04 | AI22: =12*(J22*'Programas e Observações'!$D$8+K22*'Programas e Observações'!$D$9+L22*('Programas e Observações'!$D$8+'Programas e Observações'!$D$9)+M22*'Programas e Observações'!$D$10) -> 148904.16 | AJ22: 218 moradores pegam remédio de pressão ou diabetes de graça na Farmácia Popular | AK22: Sem o programa, gastariam pelo menos R$ 75 mil por ano
A23: 1100304 | B23: 110030 | C23: Vilhena | D23: RO | E23: 11006 | F23: Cone Sul | G23: 109651 | H23: =G23<'Programas e Observações'!$C$11 -> FALSE | I23: 3793 | J23: 1954 | K23: 342 | L23: 900 | M23: 61 | N23: 957 | O23: 163 | P23: 3 | Q23: 323 | R23: =IF(G23>0,1000*I23/G23,0) -> 34.591568 | S23: =IF(G23>0,1000*J23/G23,0) -> 17.820175 | T23: =IF(G23>0,1000*K23/G23,0) -> 3.1189866 | U23: =IF(G23>0,1000*L23/G23,0) -> 8.2078595 | V23: =IF(G23>0,1000*M23/G23,0) -> 0.55631048 | W23: =IF(G23>0,1000*N23/G23,0) -> 8.7276906 | X23: =IF(G23>0,1000*O23/G23,0) -> 1.4865346 | Y23: =SUMIFS($I$2:$I$5572,$E$2:$E$5572,E23) -> 6176 | Z23: =SUMIFS($J$2:$J$5572,$E$2:$E$5572,E23) -> 3173 | AA23: =SUMIFS($K$2:$K$5572,$E$2:$E$5572,E23) -> 544 | AB23: =SUMIFS($L$2:$L$5572,$E$2:$E$5572,E23) -> 1434 | AC23: =SUMIFS($M$2:$M$5572,$E$2:$E$5572,E23) -> 238 | AD23: =SUMIFS($N$2:$N$5572,$E$2:$E$5572,E23) -> 1653 | AE23: =SUMIFS($O$2:$O$5572,$E$2:$E$5572,E23) -> 277 | AF23: =SUMIFS($P$2:$P$5572,$E$2:$E$5572,E23) -> 5 | AG23: =IF(SUMIFS($G$2:$G$5572,$E$2:$E$5572,E23)>0,1000*Y23/SUMIFS($G$2:$G$5572,$E$2:$E$5572,E23),0) -> 36.48889 | AH23: =12*(J23*'Programas e Observações'!$C$8+K23*'Programas e Observações'!$C$9+L23*('Programas e Observações'!$C$8+'Programas e Observações'!$C$9)+M23*'Programas e Observações'!$C$10) -> 1231643.3 | AI23: =12*(J23*'Programas e Observações'!$D$8+K23*'Programas e Observações'!$D$9+L23*('Programas e Observações'!$D$8+'Programas e Observações'!$D$9)+M23*'Programas e Observações'!$D$10) -> 2285754.1 | AJ23: 3.196 moradores pegam remédio de pressão ou diabetes de graça na Farmácia Popular | AK23: Sem o programa, gastariam pelo menos R$ 1,2 milhões por ano
A24: 1100320 | B24: 110032 | C24: São Miguel do Guaporé | D24: RO | E24: 11003 | F24: Central | G24: 22305 | H24: =G24<'Programas e Observações'!$C$11 -> FALSE | I24: 0 | J24: 0 | K24: 0 | L24: 0 | M24: 0 | N24: 164 | O24: 46 | P24: 1 | R24: =IF(G24>0,1000*I24/G24,0) -> 0 | S24: =IF(G24>0,1000*J24/G24,0) -> 0 | T24: =IF(G24>0,1000*K24/G24,0) -> 0 | U24: =IF(G24>0,1000*L24/G24,0) -> 0 | V24: =IF(G24>0,1000*M24/G24,0) -> 0 | W24: =IF(G24>0,1000*N24/G24,0) -> 7.3526115 | X24: =IF(G24>0,1000*O24/G24,0) -> 2.0623179 | Y24: =SUMIFS($I$2:$I$5572,$E$2:$E$5572,E24) -> 5999 | Z24: =SUMIFS($J$2:$J$5572,$E$2:$E$5572,E24) -> 2842 | AA24: =SUMIFS($K$2:$K$5572,$E$2:$E$5572,E24) -> 444 | AB24: =SUMIFS($L$2:$L$5572,$E$2:$E$5572,E24) -> 1118 | AC24: =SUMIFS($M$2:$M$5572,$E$2:$E$5572,E24) -> 101 | AD24: =SUMIFS($N$2:$N$5572,$E$2:$E$5572,E24) -> 3467 | AE24: =SUMIFS($O$2:$O$5572,$E$2:$E$5572,E24) -> 774 | AF24: =SUMIFS($P$2:$P$5572,$E$2:$E$5572,E24) -> 18 | AG24: =IF(SUMIFS($G$2:$G$5572,$E$2:$E$5572,E24)>0,1000*Y24/SUMIFS($G$2:$G$5572,$E$2:$E$5572,E24),0) -> 16.909213 | AH24: =12*(J24*'Programas e Observações'!$C$8+K24*'Programas e Observações'!$C$9+L24*('Programas e Observações'!$C$8+'Programas e Observações'!$C$9)+M24*'Programas e Observações'!$C$10) -> 0 | AI24: =12*(J24*'Programas e Observações'!$D$8+K24*'Programas e Observações'!$D$9+L24*('Programas e Observações'!$D$8+'Programas e Observações'!$D$9)+M24*'Programas e Observações'!$D$10) -> 0 | AJ24: 0 moradores pegam remédio de pressão ou diabetes de graça na Farmácia Popular | AK24: Sem o programa, gastariam pelo menos R$ 0 mil por ano
A25: 1100338 | B25: 110033 | C25: Nova Mamoré | D25: RO | E25: 11004 | F25: Madeira-Mamoré | G25: 28701 | H25: =G25<'Programas e Observações'!$C$11 -> FALSE | I25: 128 | J25: 28 | K25: 19 | L25: 20 | M25: 5 | N25: 132 | O25: 33 | P25: 0 | R25: =IF(G25>0,1000*I25/G25,0) -> 4.4597749 | S25: =IF(G25>0,1000*J25/G25,0) -> 0.97557576 | T25: =IF(G25>0,1000*K25/G25,0) -> 0.66199784 | U25: =IF(G25>0,1000*L25/G25,0) -> 0.69683983 | V25: =IF(G25>0,1000*M25/G25,0) -> 0.17420996 | W25: =IF(G25>0,1000*N25/G25,0) -> 4.5991429 | X25: =IF(G25>0,1000*O25/G25,0) -> 1.1497857 | Y25: =SUMIFS($I$2:$I$5572,$E$2:$E$5572,E25) -> 6894 | Z25: =SUMIFS($J$2:$J$5572,$E$2:$E$5572,E25) -> 1916 | AA25: =SUMIFS($K$2:$K$5572,$E$2:$E$5572,E25) -> 1016 | AB25: =SUMIFS($L$2:$L$5572,$E$2:$E$5572,E25) -> 1376 | AC25: =SUMIFS($M$2:$M$5572,$E$2:$E$5572,E25) -> 263 | AD25: =SUMIFS($N$2:$N$5572,$E$2:$E$5572,E25) -> 5769 | AE25: =SUMIFS($O$2:$O$5572,$E$2:$E$5572,E25) -> 1523 | AF25: =SUMIFS($P$2:$P$5572,$E$2:$E$5572,E25) -> 22 | AG25: =IF(SUMIFS($G$2:$G$5572,$E$2:$E$5572,E25)>0,1000*Y25/SUMIFS($G$2:$G$5572,$E$2:$E$5572,E25),0) -> 11.056139 | AH25: =12*(J25*'Programas e Observações'!$C$8+K25*'Programas e Observações'!$C$9+L25*('Programas e Observações'!$C$8+'Programas e Observações'!$C$9)+M25*'Programas e Observações'!$C$10) -> 32035.8 | AI25: =12*(J25*'Programas e Observações'!$D$8+K25*'Programas e Observações'!$D$9+L25*('Programas e Observações'!$D$8+'Programas e Observações'!$D$9)+M25*'Programas e Observações'!$D$10) -> 50212.32 | AJ25: 67 moradores pegam remédio de pressão ou diabetes de graça na Farmácia Popular | AK25: Sem o programa, gastariam pelo menos R$ 32 mil por ano
A26: 1100346 | B26: 110034 | C26: Alvorada D'Oeste | D26: RO | E26: 11003 | F26: Central | G26: 13720 | H26: =G26<'Programas e Observações'!$C$11 -> TRUE | I26: 451 | J26: 257 | K26: 31 | L26: 91 | M26: 28 | N26: 123 | O26: 36 | P26: 0 | R26: =IF(G26>0,1000*I26/G26,0) -> 32.87172 | S26: =IF(G26>0,1000*J26/G26,0) -> 18.731778 | T26: =IF(G26>0,1000*K26/G26,0) -> 2.2594752 | U26: =IF(G26>0,1000*L26/G26,0) -> 6.6326531 | V26: =IF(G26>0,1000*M26/G26,0) -> 2.0408163 | W26: =IF(G26>0,1000*N26/G26,0) -> 8.9650146 | X26: =IF(G26>0,1000*O26/G26,0) -> 2.6239067 | Y26: =SUMIFS($I$2:$I$5572,$E$2:$E$5572,E26) -> 5999 | Z26: =SUMIFS($J$2:$J$5572,$E$2:$E$5572,E26) -> 2842 | AA26: =SUMIFS($K$2:$K$5572,$E$2:$E$5572,E26) -> 444 | AB26: =SUMIFS($L$2:$L$5572,$E$2:$E$5572,E26) -> 1118 | AC26: =SUMIFS($M$2:$M$5572,$E$2:$E$5572,E26) -> 101 | AD26: =SUMIFS($N$2:$N$5572,$E$2:$E$5572,E26) -> 3467 | AE26: =SUMIFS($O$2:$O$5572,$E$2:$E$5572,E26) -> 774 | AF26: =SUMIFS($P$2:$P$5572,$E$2:$E$5572,E26) -> 18 | AG26: =IF(SUMIFS($G$2:$G$5572,$E$2:$E$5572,E26)>0,1000*Y26/SUMIFS($G$2:$G$5572,$E$2:$E$5572,E26),0) -> 16.909213 | AH26: =12*(J26*'Programas e Observações'!$C$8+K26*'Programas e Observações'!$C$9+L26*('Programas e Observações'!$C$8+'Programas e Observações'!$C$9)+M26*'Programas e Observações'!$C$10) -> 146023.44 | AI26: =12*(J26*'Programas e Observações'!$D$8+K26*'Programas e Observações'!$D$9+L26*('Programas e Observações'!$D$8+'Programas e Observações'!$D$9)+M26*'Programas e Observações'!$D$10) -> 274213.2 | AJ26: 379 moradores pegam remédio de pressão ou diabetes de graça na Farmácia Popular | AK26: Sem o programa, gastariam pelo menos R$ 146 mil por ano
A27: 1100379 | B27: 110037 | C27: Alto Alegre dos Parecis | D27: RO | E27: 11005 | F27: Zona da Mata | G27: 12237 | H27: =G27<'Programas e Observações'!$C$11 -> TRUE | I27: 522 | J27: 313 | K27: 27 | L27: 87 | M27: 22 | N27: 182 | O27: 31 | P27: 1 | R27: =IF(G27>0,1000*I27/G27,0) -> 42.657514 | S27: =IF(G27>0,1000*J27/G27,0) -> 25.578165 | T27: =IF(G27>0,1000*K27/G27,0) -> 2.2064231 | U27: =IF(G27>0,1000*L27/G27,0) -> 7.1095857 | V27: =IF(G27>0,1000*M27/G27,0) -> 1.7978263 | W27: =IF(G27>0,1000*N27/G27,0) -> 14.872926 | X27: =IF(G27>0,1000*O27/G27,0) -> 2.5333006 | Y27: =SUMIFS($I$2:$I$5572,$E$2:$E$5572,E27) -> 3387 | Z27: =SUMIFS($J$2:$J$5572,$E$2:$E$5572,E27) -> 1912 | AA27: =SUMIFS($K$2:$K$5572,$E$2:$E$5572,E27) -> 196 | AB27: =SUMIFS($L$2:$L$5572,$E$2:$E$5572,E27) -> 835 | AC27: =SUMIFS($M$2:$M$5572,$E$2:$E$5572,E27) -> 38 | AD27: =SUMIFS($N$2:$N$5572,$E$2:$E$5572,E27) -> 1751 | AE27: =SUMIFS($O$2:$O$5572,$E$2:$E$5572,E27) -> 314 | AF27: =SUMIFS($P$2:$P$5572,$E$2:$E$5572,E27) -> 7 | AG27: =IF(SUMIFS($G$2:$G$5572,$E$2:$E$5572,E27)>0,1000*Y27/SUMIFS($G$2:$G$5572,$E$2:$E$5572,E27),0) -> 24.545613 | AH27: =12*(J27*'Programas e Observações'!$C$8+K27*'Programas e Observações'!$C$9+L27*('Programas e Observações'!$C$8+'Programas e Observações'!$C$9)+M27*'Programas e Observações'!$C$10) -> 149111.76 | AI27: =12*(J27*'Programas e Observações'!$D$8+K27*'Programas e Observações'!$D$9+L27*('Programas e Observações'!$D$8+'Programas e Observações'!$D$9)+M27*'Programas e Observações'!$D$10) -> 295744.32 | AJ27: 427 moradores pegam remédio de pressão ou diabetes de graça na Farmácia Popular | AK27: Sem o programa, gastariam pelo menos R$ 149 mil por ano
A28: 1100403 | B28: 110040 | C28: Alto Paraíso | D28: RO | E28: 11001 | F28: Vale do Jamari | G28: 17467 | H28: =G28<'Programas e Observações'!$C$11 -> TRUE | I28: 188 | J28: 112 | K28: 19 | L28: 43 | M28: 0 | N28: 175 | O28: 37 | P28: 1 | R28: =IF(G28>0,1000*I28/G28,0) -> 10.763153 | S28: =IF(G28>0,1000*J28/G28,0) -> 6.4120914 | T28: =IF(G28>0,1000*K28/G28,0) -> 1.0877655 | U28: =IF(G28>0,1000*L28/G28,0) -> 2.4617851 | V28: =IF(G28>0,1000*M28/G28,0) -> 0 | W28: =IF(G28>0,1000*N28/G28,0) -> 10.018893 | X28: =IF(G28>0,1000*O28/G28,0) -> 2.1182802 | Y28: =SUMIFS($I$2:$I$5572,$E$2:$E$5572,E28) -> 3070 | Z28: =SUMIFS($J$2:$J$5572,$E$2:$E$5572,E28) -> 1523 | AA28: =SUMIFS($K$2:$K$5572,$E$2:$E$5572,E28) -> 232 | AB28: =SUMIFS($L$2:$L$5572,$E$2:$E$5572,E28) -> 477 | AC28: =SUMIFS($M$2:$M$5572,$E$2:$E$5572,E28) -> 83 | AD28: =SUMIFS($N$2:$N$5572,$E$2:$E$5572,E28) -> 2055 | AE28: =SUMIFS($O$2:$O$5572,$E$2:$E$5572,E28) -> 401 | AF28: =SUMIFS($P$2:$P$5572,$E$2:$E$5572,E28) -> 13 | AG28: =IF(SUMIFS($G$2:$G$5572,$E$2:$E$5572,E28)>0,1000*Y28/SUMIFS($G$2:$G$5572,$E$2:$E$5572,E28),0) -> 12.973622 | AH28: =12*(J28*'Programas e Observações'!$C$8+K28*'Programas e Observações'!$C$9+L28*('Programas e Observações'!$C$8+'Programas e Observações'!$C$9)+M28*'Programas e Observações'!$C$10) -> 62365.8 | AI28: =12*(J28*'Programas e Observações'!$D$8+K28*'Programas e Observações'!$D$9+L28*('Programas e Observações'!$D$8+'Programas e Observações'!$D$9)+M28*'Programas e Observações'!$D$10) -> 119449.2 | AJ28: 174 moradores pegam remédio de pressão ou diabetes de graça na Farmácia Popular | AK28: Sem o programa, gastariam pelo menos R$ 62 mil por ano
A29: 1100452 | B29: 110045 | C29: Buritis | D29: RO | E29: 11001 | F29: Vale do Jamari | G29: 30649 | H29: =G29<'Programas e Observações'!$C$11 -> FALSE | I29: 456 | J29: 209 | K29: 50 | L29: 95 | M29: 14 | N29: 287 | O29: 46 | P29: 0 | R29: =IF(G29>0,1000*I29/G29,0) -> 14.878136 | S29: =IF(G29>0,1000*J29/G29,0) -> 6.8191458 | T29: =IF(G29>0,1000*K29/G29,0) -> 1.6313746 | U29: =IF(G29>0,1000*L29/G29,0) -> 3.0996117 | V29: =IF(G29>0,1000*M29/G29,0) -> 0.45678489 | W29: =IF(G29>0,1000*N29/G29,0) -> 9.3640902 | X29: =IF(G29>0,1000*O29/G29,0) -> 1.5008646 | Y29: =SUMIFS($I$2:$I$5572,$E$2:$E$5572,E29) -> 3070 | Z29: =SUMIFS($J$2:$J$5572,$E$2:$E$5572,E29) -> 1523 | AA29: =SUMIFS($K$2:$K$5572,$E$2:$E$5572,E29) -> 232 | AB29: =SUMIFS($L$2:$L$5572,$E$2:$E$5572,E29) -> 477 | AC29: =SUMIFS($M$2:$M$5572,$E$2:$E$5572,E29) -> 83 | AD29: =SUMIFS($N$2:$N$5572,$E$2:$E$5572,E29) -> 2055 | AE29: =SUMIFS($O$2:$O$5572,$E$2:$E$5572,E29) -> 401 | AF29: =SUMIFS($P$2:$P$5572,$E$2:$E$5572,E29) -> 13 | AG29: =IF(SUMIFS($G$2:$G$5572,$E$2:$E$5572,E29)>0,1000*Y29/SUMIFS($G$2:$G$5572,$E$2:$E$5572,E29),0) -> 12.973622 | AH29: =12*(J29*'Programas e Observações'!$C$8+K29*'Programas e Observações'!$C$9+L29*('Programas e Observações'!$C$8+'Programas e Observações'!$C$9)+M29*'Programas e Observações'!$C$10) -> 141619.32 | AI29: =12*(J29*'Programas e Observações'!$D$8+K29*'Programas e Observações'!$D$9+L29*('Programas e Observações'!$D$8+'Programas e Observações'!$D$9)+M29*'Programas e Observações'!$D$10) -> 254281.8 | AJ29: 354 moradores pegam remédio de pressão ou diabetes de graça na Farmácia Popular | AK29: Sem o programa, gastariam pelo menos R$ 142 mil por ano
A30: 1100502 | B30: 110050 | C30: Novo Horizonte do Oeste | D30: RO | E30: 11005 | F30: Zona da Mata | G30: 7972 | H30: =G30<'Programas e Observações'!$C$11 -> TRUE | I30: 269 | J30: 185 | K30: 27 | L30: 50 | M30: 0 | N30: 105 | O30: 18 | P30: 0 | R30: =IF(G30>0,1000*I30/G30,0) -> 33.743101 | S30: =IF(G30>0,1000*J30/G30,0) -> 23.206222 | T30: =IF(G30>0,1000*K30/G30,0) -> 3.386854 | U30: =IF(G30>0,1000*L30/G30,0) -> 6.2719518 | V30: =IF(G30>0,1000*M30/G30,0) -> 0 | W30: =IF(G30>0,1000*N30/G30,0) -> 13.171099 | X30: =IF(G30>0,1000*O30/G30,0) -> 2.2579027 | Y30: =SUMIFS($I$2:$I$5572,$E$2:$E$5572,E30) -> 3387 | Z30: =SUMIFS($J$2:$J$5572,$E$2:$E$5572,E30) -> 1912 | AA30: =SUMIFS($K$2:$K$5572,$E$2:$E$5572,E30) -> 196 | AB30: =SUMIFS($L$2:$L$5572,$E$2:$E$5572,E30) -> 835 | AC30: =SUMIFS($M$2:$M$5572,$E$2:$E$5572,E30) -> 38 | AD30: =SUMIFS($N$2:$N$5572,$E$2:$E$5572,E30) -> 1751 | AE30: =SUMIFS($O$2:$O$5572,$E$2:$E$5572,E30) -> 314 | AF30: =SUMIFS($P$2:$P$5572,$E$2:$E$5572,E30) -> 7 | AG30: =IF(SUMIFS($G$2:$G$5572,$E$2:$E$5572,E30)>0,1000*Y30/SUMIFS($G$2:$G$5572,$E$2:$E$5572,E30),0) -> 24.545613 | AH30: =12*(J30*'Programas e Observações'!$C$8+K30*'Programas e Observações'!$C$9+L30*('Programas e Observações'!$C$8+'Programas e Observações'!$C$9)+M30*'Programas e Observações'!$C$10) -> 85894.8 | AI30: =12*(J30*'Programas e Observações'!$D$8+K30*'Programas e Observações'!$D$9+L30*('Programas e Observações'!$D$8+'Programas e Observações'!$D$9)+M30*'Programas e Observações'!$D$10) -> 172073.4 | AJ30: 262 moradores pegam remédio de pressão ou diabetes de graça na Farmácia Popular | AK30: Sem o programa, gastariam pelo menos R$ 86 mil por ano
A31: 1100601 | B31: 110060 | C31: Cacaulândia | D31: RO | E31: 11001 | F31: Vale do Jamari | G31: 4292 | H31: =G31<'Programas e Observações'!$C$11 -> TRUE | I31: 174 | J31: 100 | K31: 13 | L31: 20 | M31: 20 | N31: 77 | O31: 9 | P31: 0 | R31: =IF(G31>0,1000*I31/G31,0) -> 40.540541 | S31: =IF(G31>0,1000*J31/G31,0) -> 23.299161 | T31: =IF(G31>0,1000*K31/G31,0) -> 3.028891 | U31: =IF(G31>0,1000*L31/G31,0) -> 4.6598322 | V31: =IF(G31>0,1000*M31/G31,0) -> 4.6598322 | W31: =IF(G31>0,1000*N31/G31,0) -> 17.940354 | X31: =IF(G31>0,1000*O31/G31,0) -> 2.0969245 | Y31: =SUMIFS($I$2:$I$5572,$E$2:$E$5572,E31) -> 3070 | Z31: =SUMIFS($J$2:$J$5572,$E$2:$E$5572,E31) -> 1523 | AA31: =SUMIFS($K$2:$K$5572,$E$2:$E$5572,E31) -> 232 | AB31: =SUMIFS($L$2:$L$5572,$E$2:$E$5572,E31) -> 477 | AC31: =SUMIFS($M$2:$M$5572,$E$2:$E$5572,E31) -> 83 | AD31: =SUMIFS($N$2:$N$5572,$E$2:$E$5572,E31) -> 2055 | AE31: =SUMIFS($O$2:$O$5572,$E$2:$E$5572,E31) -> 401 | AF31: =SUMIFS($P$2:$P$5572,$E$2:$E$5572,E31) -> 13 | AG31: =IF(SUMIFS($G$2:$G$5572,$E$2:$E$5572,E31)>0,1000*Y31/SUMIFS($G$2:$G$5572,$E$2:$E$5572,E31),0) -> 12.973622 | AH31: =12*(J31*'Programas e Observações'!$C$8+K31*'Programas e Observações'!$C$9+L31*('Programas e Observações'!$C$8+'Programas e Observações'!$C$9)+M31*'Programas e Observações'!$C$10) -> 51187.8 | AI31: =12*(J31*'Programas e Observações'!$D$8+K31*'Programas e Observações'!$D$9+L31*('Programas e Observações'!$D$8+'Programas e Observações'!$D$9)+M31*'Programas e Observações'!$D$10) -> 95343 | AJ31: 133 moradores pegam remédio de pressão ou diabetes de graça na Farmácia Popular | AK31: Sem o programa, gastariam pelo menos R$ 51 mil por ano
A32: 1100700 | B32: 110070 | C32: Campo Novo de Rondônia | D32: RO | E32: 11001 | F32: Vale do Jamari | G32: 9095 | H32: =G32<'Programas e Observações'!$C$11 -> TRUE | I32: 125 | J32: 81 | K32: 11 | L32: 23 | M32: 0 | N32: 76 | O32: 14 | P32: 1 | R32: =IF(G32>0,1000*I32/G32,0) -> 13.743815 | S32: =IF(G32>0,1000*J32/G32,0) -> 8.9059923 | T32: =IF(G32>0,1000*K32/G32,0) -> 1.2094557 | U32: =IF(G32>0,1000*L32/G32,0) -> 2.528862 | V32: =IF(G32>0,1000*M32/G32,0) -> 0 | W32: =IF(G32>0,1000*N32/G32,0) -> 8.3562397 | X32: =IF(G32>0,1000*O32/G32,0) -> 1.5393073 | Y32: =SUMIFS($I$2:$I$5572,$E$2:$E$5572,E32) -> 3070 | Z32: =SUMIFS($J$2:$J$5572,$E$2:$E$5572,E32) -> 1523 | AA32: =SUMIFS($K$2:$K$5572,$E$2:$E$5572,E32) -> 232 | AB32: =SUMIFS($L$2:$L$5572,$E$2:$E$5572,E32) -> 477 | AC32: =SUMIFS($M$2:$M$5572,$E$2:$E$5572,E32) -> 83 | AD32: =SUMIFS($N$2:$N$5572,$E$2:$E$5572,E32) -> 2055 | AE32: =SUMIFS($O$2:$O$5572,$E$2:$E$5572,E32) -> 401 | AF32: =SUMIFS($P$2:$P$5572,$E$2:$E$5572,E32) -> 13 | AG32: =IF(SUMIFS($G$2:$G$5572,$E$2:$E$5572,E32)>0,1000*Y32/SUMIFS($G$2:$G$5572,$E$2:$E$5572,E32),0) -> 12.973622 | AH32: =12*(J32*'Programas e Observações'!$C$8+K32*'Programas e Observações'!$C$9+L32*('Programas e Observações'!$C$8+'Programas e Observações'!$C$9)+M32*'Programas e Observações'!$C$10) -> 37974 | AI32: =12*(J32*'Programas e Observações'!$D$8+K32*'Programas e Observações'!$D$9+L32*('Programas e Observações'!$D$8+'Programas e Observações'!$D$9)+M32*'Programas e Observações'!$D$10) -> 76110.96 | AJ32: 115 moradores pegam remédio de pressão ou diabetes de graça na Farmácia Popular | AK32: Sem o programa, gastariam pelo menos R$ 38 mil por ano
A33: 1100809 | B33: 110080 | C33: Candeias do Jamari | D33: RO | E33: 11004 | F33: Madeira-Mamoré | G33: 24313 | H33: =G33<'Programas e Observações'!$C$11 -> FALSE | I33: 330 | J33: 164 | K33: 33 | L33: 67 | M33: 17 | N33: 163 | O33: 50 | P33: 0 | R33: =IF(G33>0,1000*I33/G33,0) -> 13.572986 | S33: =IF(G33>0,1000*J33/G33,0) -> 6.7453626 | T33: =IF(G33>0,1000*K33/G33,0) -> 1.3572986 | U33: =IF(G33>0,1000*L33/G33,0) -> 2.7557274 | V33: =IF(G33>0,1000*M33/G33,0) -> 0.69921441 | W33: =IF(G33>0,1000*N33/G33,0) -> 6.7042323 | X33: =IF(G33>0,1000*O33/G33,0) -> 2.056513 | Y33: =SUMIFS($I$2:$I$5572,$E$2:$E$5572,E33) -> 6894 | Z33: =SUMIFS($J$2:$J$5572,$E$2:$E$5572,E33) -> 1916 | AA33: =SUMIFS($K$2:$K$5572,$E$2:$E$5572,E33) -> 1016 | AB33: =SUMIFS($L$2:$L$5572,$E$2:$E$5572,E33) -> 1376 | AC33: =SUMIFS($M$2:$M$5572,$E$2:$E$5572,E33) -> 263 | AD33: =SUMIFS($N$2:$N$5572,$E$2:$E$5572,E33) -> 5769 | AE33: =SUMIFS($O$2:$O$5572,$E$2:$E$5572,E33) -> 1523 | AF33: =SUMIFS($P$2:$P$5572,$E$2:$E$5572,E33) -> 22 | AG33: =IF(SUMIFS($G$2:$G$5572,$E$2:$E$5572,E33)>0,1000*Y33/SUMIFS($G$2:$G$5572,$E$2:$E$5572,E33),0) -> 11.056139 | AH33: =12*(J33*'Programas e Observações'!$C$8+K33*'Programas e Observações'!$C$9+L33*('Programas e Observações'!$C$8+'Programas e Observações'!$C$9)+M33*'Programas e Observações'!$C$10) -> 105780.36 | AI33: =12*(J33*'Programas e Observações'!$D$8+K33*'Programas e Observações'!$D$9+L33*('Programas e Observações'!$D$8+'Programas e Observações'!$D$9)+M33*'Programas e Observações'!$D$10) -> 191259.96 | AJ33: 264 moradores pegam remédio de pressão ou diabetes de graça na Farmácia Popular | AK33: Sem o programa, gastariam pelo menos R$ 106 mil por ano
A34: 1100908 | B34: 110090 | C34: Castanheiras | D34: RO | E34: 11005 | F34: Zona da Mata | G34: 3450 | H34: =G34<'Programas e Observações'!$C$11 -> TRUE | I34: 0 | J34: 0 | K34: 0 | L34: 0 | M34: 0 | N34: 34 | O34: 11 | P34: 1 | R34: =IF(G34>0,1000*I34/G34,0) -> 0 | S34: =IF(G34>0,1000*J34/G34,0) -> 0 | T34: =IF(G34>0,1000*K34/G34,0) -> 0 | U34: =IF(G34>0,1000*L34/G34,0) -> 0 | V34: =IF(G34>0,1000*M34/G34,0) -> 0 | W34: =IF(G34>0,1000*N34/G34,0) -> 9.8550725 | X34: =IF(G34>0,1000*O34/G34,0) -> 3.1884058 | Y34: =SUMIFS($I$2:$I$5572,$E$2:$E$5572,E34) -> 3387 | Z34: =SUMIFS($J$2:$J$5572,$E$2:$E$5572,E34) -> 1912 | AA34: =SUMIFS($K$2:$K$5572,$E$2:$E$5572,E34) -> 196 | AB34: =SUMIFS($L$2:$L$5572,$E$2:$E$5572,E34) -> 835 | AC34: =SUMIFS($M$2:$M$5572,$E$2:$E$5572,E34) -> 38 | AD34: =SUMIFS($N$2:$N$5572,$E$2:$E$5572,E34) -> 1751 | AE34: =SUMIFS($O$2:$O$5572,$E$2:$E$5572,E34) -> 314 | AF34: =SUMIFS($P$2:$P$5572,$E$2:$E$5572,E34) -> 7 | AG34: =IF(SUMIFS($G$2:$G$5572,$E$2:$E$5572,E34)>0,1000*Y34/SUMIFS($G$2:$G$5572,$E$2:$E$5572,E34),0) -> 24.545613 | AH34: =12*(J34*'Programas e Observações'!$C$8+K34*'Programas e Observações'!$C$9+L34*('Programas e Observações'!$C$8+'Programas e Observações'!$C$9)+M34*'Programas e Observações'!$C$10) -> 0 | AI34: =12*(J34*'Programas e Observações'!$D$8+K34*'Programas e Observações'!$D$9+L34*('Programas e Observações'!$D$8+'Programas e Observações'!$D$9)+M34*'Programas e Observações'!$D$10) -> 0 | AJ34: 0 moradores pegam remédio de pressão ou diabetes de graça na Farmácia Popular | AK34: Sem o programa, gastariam pelo menos R$ 0 mil por ano
A35: 1100924 | B35: 110092 | C35: Chupinguaia | D35: RO | E35: 11006 | F35: Cone Sul | G35: 10191 | H35: =G35<'Programas e Observações'!$C$11 -> TRUE | I35: 94 | J35: 45 | K35: 10 | L35: 17 | M35: 4 | N35: 59 | O35: 17 | P35: 0 | R35: =IF(G35>0,1000*I35/G35,0) -> 9.2238249 | S35: =IF(G35>0,1000*J35/G35,0) -> 4.4156609 | T35: =IF(G35>0,1000*K35/G35,0) -> 0.98125797 | U35: =IF(G35>0,1000*L35/G35,0) -> 1.6681386 | V35: =IF(G35>0,1000*M35/G35,0) -> 0.39250319 | W35: =IF(G35>0,1000*N35/G35,0) -> 5.789422 | X35: =IF(G35>0,1000*O35/G35,0) -> 1.6681386 | Y35: =SUMIFS($I$2:$I$5572,$E$2:$E$5572,E35) -> 6176 | Z35: =SUMIFS($J$2:$J$5572,$E$2:$E$5572,E35) -> 3173 | AA35: =SUMIFS($K$2:$K$5572,$E$2:$E$5572,E35) -> 544 | AB35: =SUMIFS($L$2:$L$5572,$E$2:$E$5572,E35) -> 1434 | AC35: =SUMIFS($M$2:$M$5572,$E$2:$E$5572,E35) -> 238 | AD35: =SUMIFS($N$2:$N$5572,$E$2:$E$5572,E35) -> 1653 | AE35: =SUMIFS($O$2:$O$5572,$E$2:$E$5572,E35) -> 277 | AF35: =SUMIFS($P$2:$P$5572,$E$2:$E$5572,E35) -> 5 | AG35: =IF(SUMIFS($G$2:$G$5572,$E$2:$E$5572,E35)>0,1000*Y35/SUMIFS($G$2:$G$5572,$E$2:$E$5572,E35),0) -> 36.48889 | AH35: =12*(J35*'Programas e Observações'!$C$8+K35*'Programas e Observações'!$C$9+L35*('Programas e Observações'!$C$8+'Programas e Observações'!$C$9)+M35*'Programas e Observações'!$C$10) -> 28176.12 | AI35: =12*(J35*'Programas e Observações'!$D$8+K35*'Programas e Observações'!$D$9+L35*('Programas e Observações'!$D$8+'Programas e Observações'!$D$9)+M35*'Programas e Observações'!$D$10) -> 51114.12 | AJ35: 72 moradores pegam remédio de pressão ou diabetes de graça na Farmácia Popular | AK35: Sem o programa, gastariam pelo menos R$ 28 mil por ano
... A58: 1200179 | B58: 120017 | C58: Capixaba | D58: AC | E58: 12002 | F58: Baixo Acre e Purus | G58: 10981 | H58: =G58<'Programas e Observações'!$C$11 -> TRUE | I58: 0 | J58: 0 | K58: 0 | L58: 0 | M58: 0 | N58: 31 | O58: 6 | P58: 0 | R58: =IF(G58>0,1000*I58/G58,0) -> 0 | S58: =IF(G58>0,1000*J58/G58,0) -> 0 | T58: =IF(G58>0,1000*K58/G58,0) -> 0 | U58: =IF(G58>0,1000*L58/G58,0) -> 0 | V58: =IF(G58>0,1000*M58/G58,0) -> 0 | W58: =IF(G58>0,1000*N58/G58,0) -> 2.823058 | X58: =IF(G58>0,1000*O58/G58,0) -> 0.54639832 | Y58: =SUMIFS($I$2:$I$5572,$E$2:$E$5572,E58) -> 4168 | Z58: =SUMIFS($J$2:$J$5572,$E$2:$E$5572,E58) -> 877 | AA58: =SUMIFS($K$2:$K$5572,$E$2:$E$5572,E58) -> 267 | AB58: =SUMIFS($L$2:$L$5572,$E$2:$E$5572,E58) -> 346 | AC58: =SUMIFS($M$2:$M$5572,$E$2:$E$5572,E58) -> 37 | AD58: =SUMIFS($N$2:$N$5572,$E$2:$E$5572,E58) -> 3474 | AE58: =SUMIFS($O$2:$O$5572,$E$2:$E$5572,E58) -> 518 | AF58: =SUMIFS($P$2:$P$5572,$E$2:$E$5572,E58) -> 20 | AG58: =IF(SUMIFS($G$2:$G$5572,$E$2:$E$5572,E58)>0,1000*Y58/SUMIFS($G$2:$G$5572,$E$2:$E$5572,E58),0) -> 7.4464873 | AH58: =12*(J58*'Programas e Observações'!$C$8+K58*'Programas e Observações'!$C$9+L58*('Programas e Observações'!$C$8+'Programas e Observações'!$C$9)+M58*'Programas e Observações'!$C$10) -> 0 | AI58: =12*(J58*'Programas e Observações'!$D$8+K58*'Programas e Observações'!$D$9+L58*('Programas e Observações'!$D$8+'Programas e Observações'!$D$9)+M58*'Programas e Observações'!$D$10) -> 0 | AJ58: 0 moradores pegam remédio de pressão ou diabetes de graça na Farmácia Popular | AK58: Sem o programa, gastariam pelo menos R$ 0 mil por ano
